Workbook

Sheet Assumptions
A1: Sarab Studio · ABANDONED · financial workbook
A2: Money is in AED, with US dollars beside it at the fixed rate in B32 (AED 3.6725 to the dollar). Yellow cells are inputs: change one and the price, revenue, cash and payback figures recalculate. Estimates, not audited.
A4: Price to net | B4: Value | E4: Note
A5: List price | B5: 36.7 | E5: One-time purchase
A6: Average sale after regional prices and discounts | B6: 0.78 | E6: Share of list price
A7: Sales tax and VAT inside the price | B7: 0.06
A8: Refunds | B8: 0.04
A9: Steam's share | B9: 0.3
A10: US buyers, share of revenue | B10: 0.3 | E10: Assumption
A11: US tax withheld on US sales | B11: 0.3 | E11: No US–UAE income tax treaty, so Valve withholds 30%
A12: What the studio keeps per copy | B12: =B5*B6*(1-B7)*(1-B8)*(1-B9)*(1-B10*B11) -> 16.455
A13: DLC price | B13: 18.35
A14: What the studio keeps per DLC copy | B14: =B13*B12/B5 -> 8.2275
A16: Scenarios | B16: Downside | C16: Base | D16: Upside
A17: Wishlists at launch | B17: 5000 | C17: 15000 | D17: 60000
A18: Copies in year one | B18: 8000 | C18: 30000 | D18: 150000
A23: Year-two copies, share of year one | B23: 0.35
A24: Year-three copies, share of year one | B24: 0.15
A25: Steam pays | B25: About 30 days after each month's sales
A27: Break-even | B27: AED
A28: Plan total | B28: =Budget!B15 -> 308100
A29: Copies to repay the plan | B29: =B28/B12 -> 18724
A31: US dollars | B31: AED | C31: USD | E31: The dirham is pegged to the dollar, so this rate does not move
A32: AED per US dollar (fixed rate) | B32: 3.6725
A33: List price | B33: =B5 -> 36.7 | C33: =B33/$B$32 -> 9.9932
A34: What the studio keeps per copy | B34: =B12 -> 16.455 | C34: =B34/$B$32 -> 4.4806
A35: DLC price | B35: =B13 -> 18.35 | C35: =B35/$B$32 -> 4.9966
A36: What the studio keeps per DLC copy | B36: =B14 -> 8.2275 | C36: =B36/$B$32 -> 2.2403
A37: Plan total | B37: =B28 -> 308100 | C37: =B37/$B$32 -> 83893.805

Sheet Budget
A1: Budget line by line, November 2026 to December 2027 (AED, with US dollars)
A2: Line | B2: AED | C2: USD | D2: What it covers
A3: Founders | B3: 127300 | C3: =B3/Assumptions!$B$32 -> 34663.04 | D3: Zeyad and Yousef: 30,000 with tranche 1 and 20,000 with tranche 3, each. Jihad: 16,400 and 10,900
A4: UAE interns, 6 months | B4: 30000 | C4: =B4/Assumptions!$B$32 -> 8168.82 | D4: 2 interns at 2,500 a month each, November to April
A5: Company setup | B5: 10000 | C5: =B5/Assumptions!$B$32 -> 2722.94 | D5: Registration, visa and government fees, a desk if needed; twofour54 waives licence and registration fees for two years
A6: Legal and accounting | B6: 11000 | C6: =B6/Assumptions!$B$32 -> 2995.23 | D6: Shareholder agreement, corporate tax registration, bookkeeping
A7: Test hardware | B7: 5500 | C7: =B7/Assumptions!$B$32 -> 1497.62 | D7: A Windows test PC
A8: Software and fees | B8: 15900 | C8: =B8/Assumptions!$B$32 -> 4329.48 | D8: Claude, Codex through ChatGPT, Google Workspace, the domain, the Steam Direct fee
A9: Localization | B9: 6600 | C9: =B9/Assumptions!$B$32 -> 1797.14 | D9: Native-speaker review of the translations; an Arabic proofread
A10: QA and playtesting | B10: 1800 | C10: =B10/Assumptions!$B$32 -> 490.13 | D10: Playtest sessions
A11: Marketing | B11: 70200 | C11: =B11/Assumptions!$B$32 -> 19115.04 | D11: The marketing plan in the business plan, section 7
A12: Events | B12: 1800 | C12: =B12/Assumptions!$B$32 -> 490.13 | D12: Showcase materials
A13: Contingency | B13: 28000 | C13: =B13/Assumptions!$B$32 -> 7624.23 | D13: Held in reserve (about 9%); released only against agreed overruns
A14: Total | B14: =SUM(B3:B13) -> 308100 | C14: =B14/Assumptions!$B$32 -> 83893.81
A15: Total (referenced by other sheets) | B15: =B14 -> 308100
A17: Tranches | B17: AED | C17: USD | D17: Released when
A18: 1: November 2026 to February 2027 | B18: 185330 | C18: =B18/Assumptions!$B$32 -> 50464.26 | D18: At signing
A19: 2: March to August 2027 | B19: 35122 | C19: =B19/Assumptions!$B$32 -> 9563.51 | D19: End of February 2027, if at least 10,000 copies sold and reviews at least 75% positive
A20: 3: September to December 2027 | B20: 59648 | C20: =B20/Assumptions!$B$32 -> 16241.8 | D20: After the third DLC ships, if at least 20,000 copies sold
A21: Reserve | B21: 28000 | C21: =B21/Assumptions!$B$32 -> 7624.23 | D21: Only against overruns agreed with the investor
A22: Total | B22: =SUM(B18:B21) -> 308100 | C22: =B22/Assumptions!$B$32 -> 83893.81
A24: Founder pay inside the tranches (AED) | B24: Tranche 1 | C24: Tranche 3 | D24: Total
A25: Zeyad | B25: 30000 | C25: 20000 | D25: =B25+C25 -> 50000
A26: Yousef | B26: 30000 | C26: 20000 | D26: =B26+C26 -> 50000
A27: Jihad | B27: 16400 | C27: 10900 | D27: =B27+C27 -> 27300
A28: Total | B28: =SUM(B25:B27) -> 76400 | C28: =SUM(C25:C27) -> 50900 | D28: =SUM(D25:D27) -> 127300
A30: A tranche is one instalment of the funding. Each is paid only when the milestone before it is met, so if the launch misses, the investor stops after tranche 1.

Sheet Three-year summary
A1: Three-year summary (AED, with US dollars): the studio's own cash, before anything flows back to the investor
A3: Downside case | B3: Nov–Dec 2026 (AED) | C3: 2027 (AED) | D3: 2028 (AED) | E3: 2029 (AED) | F3: Nov–Dec 2026 (USD) | G3: 2027 (USD) | H3: 2028 (USD) | I3: 2029 (USD)
A4: Paid by Steam | B4: =SUMPRODUCT((LEFT(Monthly!$A$4:$A$41,4)="2026")*Monthly!G4:G41) -> 0 | C4: =SUMPRODUCT((LEFT(Monthly!$A$4:$A$41,4)="2027")*Monthly!G4:G41) -> 147437 | D4: =SUMPRODUCT((LEFT(Monthly!$A$4:$A$41,4)="2028")*Monthly!G4:G41) -> 51603 | E4: =SUMPRODUCT((LEFT(Monthly!$A$4:$A$41,4)="2029")*Monthly!G4:G41) -> 22116 | F4: =B4/Assumptions!$B$32 -> 0 | G4: =C4/Assumptions!$B$32 -> 40146.22 | H4: =D4/Assumptions!$B$32 -> 14051.19 | I4: =E4/Assumptions!$B$32 -> 6022.06
A5: Funding received | B5: =SUMPRODUCT((LEFT(Monthly!$A$4:$A$41,4)="2026")*Monthly!H4:H41) -> 185330 | C5: =SUMPRODUCT((LEFT(Monthly!$A$4:$A$41,4)="2027")*Monthly!H4:H41) -> 0 | D5: =SUMPRODUCT((LEFT(Monthly!$A$4:$A$41,4)="2028")*Monthly!H4:H41) -> 0 | E5: =SUMPRODUCT((LEFT(Monthly!$A$4:$A$41,4)="2029")*Monthly!H4:H41) -> 0 | F5: =B5/Assumptions!$B$32 -> 50464.26 | G5: =C5/Assumptions!$B$32 -> 0 | H5: =D5/Assumptions!$B$32 -> 0 | I5: =E5/Assumptions!$B$32 -> 0
A6: Spending | B6: =SUMPRODUCT((LEFT(Monthly!$A$4:$A$41,4)="2026")*Monthly!I4:I41) -> 118676 | C6: =SUMPRODUCT((LEFT(Monthly!$A$4:$A$41,4)="2027")*Monthly!I4:I41) -> 81857 | D6: =SUMPRODUCT((LEFT(Monthly!$A$4:$A$41,4)="2028")*Monthly!I4:I41) -> 20327 | E6: =SUMPRODUCT((LEFT(Monthly!$A$4:$A$41,4)="2029")*Monthly!I4:I41) -> 30744 | F6: =B6/Assumptions!$B$32 -> 32314.77 | G6: =C6/Assumptions!$B$32 -> 22289.18 | H6: =D6/Assumptions!$B$32 -> 5534.92 | I6: =E6/Assumptions!$B$32 -> 8371.41
A7: Cash at year end | B7: =Monthly!J5 -> 66654 | C7: =Monthly!J17 -> 132234 | D7: =Monthly!J29 -> 163510 | E7: =Monthly!J41 -> 154881 | F7: =B7/Assumptions!$B$32 -> 18149.49 | G7: =C7/Assumptions!$B$32 -> 36006.54 | H7: =D7/Assumptions!$B$32 -> 44522.8 | I7: =E7/Assumptions!$B$32 -> 42173.18
A9: Base case | B9: Nov–Dec 2026 (AED) | C9: 2027 (AED) | D9: 2028 (AED) | E9: 2029 (AED) | F9: Nov–Dec 2026 (USD) | G9: 2027 (USD) | H9: 2028 (USD) | I9: 2029 (USD)
A10: Paid by Steam | B10: =SUMPRODUCT((LEFT(Monthly!$A$4:$A$41,4)="2026")*Monthly!O4:O41) -> 0 | C10: =SUMPRODUCT((LEFT(Monthly!$A$4:$A$41,4)="2027")*Monthly!O4:O41) -> 609660 | D10: =SUMPRODUCT((LEFT(Monthly!$A$4:$A$41,4)="2028")*Monthly!O4:O41) -> 213381 | E10: =SUMPRODUCT((LEFT(Monthly!$A$4:$A$41,4)="2029")*Monthly!O4:O41) -> 91449 | F10: =B10/Assumptions!$B$32 -> 0 | G10: =C10/Assumptions!$B$32 -> 166006.81 | H10: =D10/Assumptions!$B$32 -> 58102.38 | I10: =E10/Assumptions!$B$32 -> 24901.02
A11: Funding received | B11: =SUMPRODUCT((LEFT(Monthly!$A$4:$A$41,4)="2026")*Monthly!P4:P41) -> 185330 | C11: =SUMPRODUCT((LEFT(Monthly!$A$4:$A$41,4)="2027")*Monthly!P4:P41) -> 94770 | D11: =SUMPRODUCT((LEFT(Monthly!$A$4:$A$41,4)="2028")*Monthly!P4:P41) -> 0 | E11: =SUMPRODUCT((LEFT(Monthly!$A$4:$A$41,4)="2029")*Monthly!P4:P41) -> 0 | F11: =B11/Assumptions!$B$32 -> 50464.26 | G11: =C11/Assumptions!$B$32 -> 25805.31 | H11: =D11/Assumptions!$B$32 -> 0 | I11: =E11/Assumptions!$B$32 -> 0
A12: Spending | B12: =SUMPRODUCT((LEFT(Monthly!$A$4:$A$41,4)="2026")*Monthly!Q4:Q41) -> 118676 | C12: =SUMPRODUCT((LEFT(Monthly!$A$4:$A$41,4)="2027")*Monthly!Q4:Q41) -> 161424 | D12: =SUMPRODUCT((LEFT(Monthly!$A$4:$A$41,4)="2028")*Monthly!Q4:Q41) -> 28327 | E12: =SUMPRODUCT((LEFT(Monthly!$A$4:$A$41,4)="2029")*Monthly!Q4:Q41) -> 38744 | F12: =B12/Assumptions!$B$32 -> 32314.77 | G12: =C12/Assumptions!$B$32 -> 43954.8 | H12: =D12/Assumptions!$B$32 -> 7713.27 | I12: =E12/Assumptions!$B$32 -> 10549.76
A13: Cash at year end | B13: =Monthly!R5 -> 66654 | C13: =Monthly!R17 -> 609660 | D13: =Monthly!R29 -> 794713 | E13: =Monthly!R41 -> 847418 | F13: =B13/Assumptions!$B$32 -> 18149.49 | G13: =C13/Assumptions!$B$32 -> 166006.81 | H13: =D13/Assumptions!$B$32 -> 216395.64 | I13: =E13/Assumptions!$B$32 -> 230746.9
A15: Upside case | B15: Nov–Dec 2026 (AED) | C15: 2027 (AED) | D15: 2028 (AED) | E15: 2029 (AED) | F15: Nov–Dec 2026 (USD) | G15: 2027 (USD) | H15: 2028 (USD) | I15: 2029 (USD)
A16: Paid by Steam | B16: =SUMPRODUCT((LEFT(Monthly!$A$4:$A$41,4)="2026")*Monthly!W4:W41) -> 0 | C16: =SUMPRODUCT((LEFT(Monthly!$A$4:$A$41,4)="2027")*Monthly!W4:W41) -> 3245758 | D16: =SUMPRODUCT((LEFT(Monthly!$A$4:$A$41,4)="2028")*Monthly!W4:W41) -> 1136015 | E16: =SUMPRODUCT((LEFT(Monthly!$A$4:$A$41,4)="2029")*Monthly!W4:W41) -> 486864 | F16: =B16/Assumptions!$B$32 -> 0 | G16: =C16/Assumptions!$B$32 -> 883800.68 | H16: =D16/Assumptions!$B$32 -> 309330.16 | I16: =E16/Assumptions!$B$32 -> 132570.18
A17: Funding received | B17: =SUMPRODUCT((LEFT(Monthly!$A$4:$A$41,4)="2026")*Monthly!X4:X41) -> 185330 | C17: =SUMPRODUCT((LEFT(Monthly!$A$4:$A$41,4)="2027")*Monthly!X4:X41) -> 94770 | D17: =SUMPRODUCT((LEFT(Monthly!$A$4:$A$41,4)="2028")*Monthly!X4:X41) -> 0 | E17: =SUMPRODUCT((LEFT(Monthly!$A$4:$A$41,4)="2029")*Monthly!X4:X41) -> 0 | F17: =B17/Assumptions!$B$32 -> 50464.26 | G17: =C17/Assumptions!$B$32 -> 25805.31 | H17: =D17/Assumptions!$B$32 -> 0 | I17: =E17/Assumptions!$B$32 -> 0
A18: Spending | B18: =SUMPRODUCT((LEFT(Monthly!$A$4:$A$41,4)="2026")*Monthly!Y4:Y41) -> 118676 | C18: =SUMPRODUCT((LEFT(Monthly!$A$4:$A$41,4)="2027")*Monthly!Y4:Y41) -> 161424 | D18: =SUMPRODUCT((LEFT(Monthly!$A$4:$A$41,4)="2028")*Monthly!Y4:Y41) -> 28327 | E18: =SUMPRODUCT((LEFT(Monthly!$A$4:$A$41,4)="2029")*Monthly!Y4:Y41) -> 38744 | F18: =B18/Assumptions!$B$32 -> 32314.77 | G18: =C18/Assumptions!$B$32 -> 43954.8 | H18: =D18/Assumptions!$B$32 -> 7713.27 | I18: =E18/Assumptions!$B$32 -> 10549.76
A19: Cash at year end | B19: =Monthly!Z5 -> 66654 | C19: =Monthly!Z17 -> 3245758 | D19: =Monthly!Z29 -> 4353447 | E19: =Monthly!Z41 -> 4801566 | F19: =B19/Assumptions!$B$32 -> 18149.49 | G19: =C19/Assumptions!$B$32 -> 883800.68 | H19: =D19/Assumptions!$B$32 -> 1185417.8 | I19: =E19/Assumptions!$B$32 -> 1307438
A21: Payback: month cumulative Steam payments reach the plan total | B21: Plan
A22: Downside | B22: =IFERROR(INDEX(Monthly!$A$4:$A$41,MATCH(TRUE,INDEX(Monthly!$K$4:$K$41>=Budget!$B$15,0),0)),"Not by end 2029") -> Not by end 2029
A23: Base | B23: =IFERROR(INDEX(Monthly!$A$4:$A$41,MATCH(TRUE,INDEX(Monthly!$S$4:$S$41>=Budget!$B$15,0),0)),"Not by end 2029") -> 2027-04
A24: Upside | B24: =IFERROR(INDEX(Monthly!$A$4:$A$41,MATCH(TRUE,INDEX(Monthly!$AA$4:$AA$41>=Budget!$B$15,0),0)),"Not by end 2029") -> 2027-01
A26: Left out on purpose: console ports, DLC after the third pack, a second game, publishing, and any founder pay after 2027. Figures are before UAE corporate tax. Estimates, not audited.

Sheet Monthly
A1: Month by month, all three cases (AED)
A2: Copies = year-one copies × the year's factor × the month's share. Net sales = copies × what the studio keeps + DLC copies × DLC keep. Steam pays a month later. Funding follows the tranche gates; in the downside only tranche 1 is drawn. Divide by Assumptions!B32 for US dollars.
A3: Month | B3: Sales year | C3: Share of the year's sales | D3: Downside: Copies sold | E3: Downside: DLC copies sold | F3: Downside: Net sales | G3: Downside: Paid by Steam | H3: Downside: Funding received | I3: Downside: Spending | J3: Downside: Cash balance | K3: Downside: Cumulative paid by Steam | L3: Base: Copies sold | M3: Base: DLC copies sold | N3: Base: Net sales | O3: Base: Paid by Steam | P3: Base: Funding received | Q3: Base: Spending | R3: Base: Cash balance | S3: Base: Cumulative paid by Steam | T3: Upside: Copies sold | U3: Upside: DLC copies sold | V3: Upside: Net sales | W3: Upside: Paid by Steam | X3: Upside: Funding received | Y3: Upside: Spending | Z3: Upside: Cash balance | AA3: Upside: Cumulative paid by Steam
A4: 2026-11 | C4: 0 | D4: 0 | E4: 0 | F4: =D4*Assumptions!$B$12+E4*Assumptions!$B$14 -> 0 | G4: 0 | H4: 185330 | I4: 68735.71 | J4: =G4+H4-I4 -> 116594.29 | K4: =G4 -> 0 | L4: 0 | M4: 0 | N4: =L4*Assumptions!$B$12+M4*Assumptions!$B$14 -> 0 | O4: 0 | P4: 185330 | Q4: 68735.71 | R4: =O4+P4-Q4 -> 116594.29 | S4: =O4 -> 0 | T4: 0 | U4: 0 | V4: =T4*Assumptions!$B$12+U4*Assumptions!$B$14 -> 0 | W4: 0 | X4: 185330 | Y4: 68735.71 | Z4: =W4+X4-Y4 -> 116594.29 | AA4: =W4 -> 0
A5: 2026-12 | B5: 1 | C5: 0.3 | D5: =Assumptions!$B$18*1*$C5 -> 2400 | E5: 0 | F5: =D5*Assumptions!$B$12+E5*Assumptions!$B$14 -> 39492.12 | G5: =F4 -> 0 | H5: 0 | I5: 49940.33 | J5: =J4+G5+H5-I5 -> 66653.96 | K5: =K4+G5 -> 0 | L5: =Assumptions!$C$18*1*$C5 -> 9000 | M5: 0 | N5: =L5*Assumptions!$B$12+M5*Assumptions!$B$14 -> 148095.44 | O5: =N4 -> 0 | P5: 0 | Q5: 49940.33 | R5: =R4+O5+P5-Q5 -> 66653.96 | S5: =S4+O5 -> 0 | T5: =Assumptions!$D$18*1*$C5 -> 45000 | U5: 0 | V5: =T5*Assumptions!$B$12+U5*Assumptions!$B$14 -> 740477.22 | W5: =V4 -> 0 | X5: 0 | Y5: 49940.33 | Z5: =Z4+W5+X5-Y5 -> 66653.96 | AA5: =AA4+W5 -> 0
A6: 2027-01 | B6: 1 | C6: 0.18 | D6: =Assumptions!$B$18*1*$C6 -> 1440 | E6: 192 | F6: =D6*Assumptions!$B$12+E6*Assumptions!$B$14 -> 25274.96 | G6: =F5 -> 39492.12 | H6: 0 | I6: 40367 | J6: =J5+G6+H6-I6 -> 65779.08 | K6: =K5+G6 -> 39492.12 | L6: =Assumptions!$C$18*1*$C6 -> 5400 | M6: 1440 | N6: =L6*Assumptions!$B$12+M6*Assumptions!$B$14 -> 100704.9 | O6: =N5 -> 148095.44 | P6: 0 | Q6: 40367 | R6: =R5+O6+P6-Q6 -> 174382.4 | S6: =S5+O6 -> 148095.44 | T6: =Assumptions!$D$18*1*$C6 -> 27000 | U6: 9000 | V6: =T6*Assumptions!$B$12+U6*Assumptions!$B$14 -> 518334.05 | W6: =V5 -> 740477.22 | X6: 0 | Y6: 40367 | Z6: =Z5+W6+X6-Y6 -> 766764.18 | AA6: =AA5+W6 -> 740477.22
A7: 2027-02 | B7: 1 | C7: 0.08 | D7: =Assumptions!$B$18*1*$C7 -> 640 | E7: 96 | F7: =D7*Assumptions!$B$12+E7*Assumptions!$B$14 -> 11321.07 | G7: =F6 -> 25274.96 | H7: 0 | I7: 26287 | J7: =J6+G7+H7-I7 -> 64767.04 | K7: =K6+G7 -> 64767.07 | L7: =Assumptions!$C$18*1*$C7 -> 2400 | M7: 720 | N7: =L7*Assumptions!$B$12+M7*Assumptions!$B$14 -> 45415.94 | O7: =N6 -> 100704.9 | P7: 0 | Q7: 26287 | R7: =R6+O7+P7-Q7 -> 248800.31 | S7: =S6+O7 -> 248800.34 | T7: =Assumptions!$D$18*1*$C7 -> 12000 | U7: 4500 | V7: =T7*Assumptions!$B$12+U7*Assumptions!$B$14 -> 234484.45 | W7: =V6 -> 518334.05 | X7: 0 | Y7: 26287 | Z7: =Z6+W7+X7-Y7 -> 1258811.2 | AA7: =AA6+W7 -> 1258811.3
A8: 2027-03 | B8: 1 | C8: 0.07 | D8: =Assumptions!$B$18*1*$C8 -> 560 | E8: 289.6 | F8: =D8*Assumptions!$B$12+E8*Assumptions!$B$14 -> 11597.52 | G8: =F7 -> 11321.07 | H8: 0 | I8: 1520.33 | J8: =J7+G8+H8-I8 -> 74567.78 | K8: =K7+G8 -> 76088.15 | L8: =Assumptions!$C$18*1*$C8 -> 2100 | M8: 2077.5 | N8: =L8*Assumptions!$B$12+M8*Assumptions!$B$14 -> 51648.29 | O8: =N7 -> 45415.94 | P8: 35122 | Q8: 13187 | R8: =R7+O8+P8-Q8 -> 316151.25 | S8: =S7+O8 -> 294216.28 | T8: =Assumptions!$D$18*1*$C8 -> 10500 | U8: 13575 | V8: =T8*Assumptions!$B$12+U8*Assumptions!$B$14 -> 284466.66 | W8: =V7 -> 234484.45 | X8: 35122 | Y8: 13187 | Z8: =Z7+W8+X8-Y8 -> 1515230.7 | AA8: =AA7+W8 -> 1493295.7
A9: 2027-04 | B9: 1 | C9: 0.05 | D9: =Assumptions!$B$18*1*$C9 -> 400 | E9: 137.6 | F9: =D9*Assumptions!$B$12+E9*Assumptions!$B$14 -> 7714.13 | G9: =F8 -> 11597.52 | H9: 0 | I9: 1520.33 | J9: =J8+G9+H9-I9 -> 84644.97 | K9: =K8+G9 -> 87685.67 | L9: =Assumptions!$C$18*1*$C9 -> 1500 | M9: 1001.25 | N9: =L9*Assumptions!$B$12+M9*Assumptions!$B$14 -> 32920.38 | O9: =N8 -> 51648.29 | P9: 0 | Q9: 7187 | R9: =R8+O9+P9-Q9 -> 360612.54 | S9: =S8+O9 -> 345864.57 | T9: =Assumptions!$D$18*1*$C9 -> 7500 | U9: 6450 | V9: =T9*Assumptions!$B$12+U9*Assumptions!$B$14 -> 176480.4 | W9: =V8 -> 284466.66 | X9: 0 | Y9: 7187 | Z9: =Z8+W9+X9-Y9 -> 1792510.4 | AA9: =AA8+W9 -> 1777762.4
A10: 2027-05 | B10: 1 | C10: 0.06 | D10: =Assumptions!$B$18*1*$C10 -> 480 | E10: 329.6 | F10: =D10*Assumptions!$B$12+E10*Assumptions!$B$14 -> 10610.22 | G10: =F9 -> 7714.13 | H10: 0 | I10: 1520.33 | J10: =J9+G10+H10-I10 -> 90838.77 | K10: =K9+G10 -> 95399.79 | L10: =Assumptions!$C$18*1*$C10 -> 1800 | M10: 2438.25 | N10: =L10*Assumptions!$B$12+M10*Assumptions!$B$14 -> 49679.85 | O10: =N9 -> 32920.38 | P10: 0 | Q10: 8187 | R10: =R9+O10+P10-Q10 -> 385345.92 | S10: =S9+O10 -> 378784.95 | T10: =Assumptions!$D$18*1*$C10 -> 9000 | U10: 17115 | V10: =T10*Assumptions!$B$12+U10*Assumptions!$B$14 -> 288909.53 | W10: =V9 -> 176480.4 | X10: 0 | Y10: 8187 | Z10: =Z9+W10+X10-Y10 -> 1960803.8 | AA10: =AA9+W10 -> 1954242.8
A11: 2027-06 | B11: 1 | C11: 0.06 | D11: =Assumptions!$B$18*1*$C11 -> 480 | E11: 210.4 | F11: =D11*Assumptions!$B$12+E11*Assumptions!$B$14 -> 9629.49 | G11: =F10 -> 10610.22 | H11: 0 | I11: 1520.33 | J11: =J10+G11+H11-I11 -> 99928.65 | K11: =K10+G11 -> 106010.01 | L11: =Assumptions!$C$18*1*$C11 -> 1800 | M11: 1544.25 | N11: =L11*Assumptions!$B$12+M11*Assumptions!$B$14 -> 42324.44 | O11: =N10 -> 49679.85 | P11: 0 | Q11: 2187 | R11: =R10+O11+P11-Q11 -> 432838.78 | S11: =S10+O11 -> 428464.8 | T11: =Assumptions!$D$18*1*$C11 -> 9000 | U11: 10410 | V11: =T11*Assumptions!$B$12+U11*Assumptions!$B$14 -> 233743.97 | W11: =V10 -> 288909.53 | X11: 0 | Y11: 2187 | Z11: =Z10+W11+X11-Y11 -> 2247526.3 | AA11: =AA10+W11 -> 2243152.3
A12: 2027-07 | B12: 1 | C12: 0.04 | D12: =Assumptions!$B$18*1*$C12 -> 320 | E12: 172 | F12: =D12*Assumptions!$B$12+E12*Assumptions!$B$14 -> 6680.75 | G12: =F11 -> 9629.49 | H12: 0 | I12: 1520.33 | J12: =J11+G12+H12-I12 -> 108037.82 | K12: =K11+G12 -> 115639.5 | L12: =Assumptions!$C$18*1*$C12 -> 1200 | M12: 1262.25 | N12: =L12*Assumptions!$B$12+M12*Assumptions!$B$14 -> 30131.25 | O12: =N11 -> 42324.44 | P12: 0 | Q12: 2187 | R12: =R11+O12+P12-Q12 -> 472976.22 | S12: =S11+O12 -> 470789.24 | T12: =Assumptions!$D$18*1*$C12 -> 6000 | U12: 8520 | V12: =T12*Assumptions!$B$12+U12*Assumptions!$B$14 -> 168828.81 | W12: =V11 -> 233743.97 | X12: 0 | Y12: 2187 | Z12: =Z11+W12+X12-Y12 -> 2479083.3 | AA12: =AA11+W12 -> 2476896.3
A13: 2027-08 | B13: 1 | C13: 0.03 | D13: =Assumptions!$B$18*1*$C13 -> 240 | E13: 120.8 | F13: =D13*Assumptions!$B$12+E13*Assumptions!$B$14 -> 4943.1 | G13: =F12 -> 6680.75 | H13: 0 | I13: 1520.33 | J13: =J12+G13+H13-I13 -> 113198.24 | K13: =K12+G13 -> 122320.25 | L13: =Assumptions!$C$18*1*$C13 -> 900 | M13: 881.25 | N13: =L13*Assumptions!$B$12+M13*Assumptions!$B$14 -> 22060.05 | O13: =N12 -> 30131.25 | P13: 0 | Q13: 2187 | R13: =R12+O13+P13-Q13 -> 500920.48 | S13: =S12+O13 -> 500920.49 | T13: =Assumptions!$D$18*1*$C13 -> 4500 | U13: 6075 | V13: =T13*Assumptions!$B$12+U13*Assumptions!$B$14 -> 124029.93 | W13: =V12 -> 168828.81 | X13: 0 | Y13: 2187 | Z13: =Z12+W13+X13-Y13 -> 2645725.1 | AA13: =AA12+W13 -> 2645725.1
A14: 2027-09 | B14: 1 | C14: 0.03 | D14: =Assumptions!$B$18*1*$C14 -> 240 | E14: 120.8 | F14: =D14*Assumptions!$B$12+E14*Assumptions!$B$14 -> 4943.1 | G14: =F13 -> 4943.1 | H14: 0 | I14: 1520.33 | J14: =J13+G14+H14-I14 -> 116621.01 | K14: =K13+G14 -> 127263.35 | L14: =Assumptions!$C$18*1*$C14 -> 900 | M14: 881.25 | N14: =L14*Assumptions!$B$12+M14*Assumptions!$B$14 -> 22060.05 | O14: =N13 -> 22060.05 | P14: 59648 | Q14: 14912 | R14: =R13+O14+P14-Q14 -> 567716.53 | S14: =S13+O14 -> 522980.55 | T14: =Assumptions!$D$18*1*$C14 -> 4500 | U14: 6075 | V14: =T14*Assumptions!$B$12+U14*Assumptions!$B$14 -> 124029.93 | W14: =V13 -> 124029.93 | X14: 59648 | Y14: 14912 | Z14: =Z13+W14+X14-Y14 -> 2814491 | AA14: =AA13+W14 -> 2769755
A15: 2027-10 | B15: 1 | C15: 0.04 | D15: =Assumptions!$B$18*1*$C15 -> 320 | E15: 106.4 | F15: =D15*Assumptions!$B$12+E15*Assumptions!$B$14 -> 6141.02 | G15: =F14 -> 4943.1 | H15: 0 | I15: 1520.33 | J15: =J14+G15+H15-I15 -> 120043.77 | K15: =K14+G15 -> 132206.45 | L15: =Assumptions!$C$18*1*$C15 -> 1200 | M15: 786 | N15: =L15*Assumptions!$B$12+M15*Assumptions!$B$14 -> 26212.89 | O15: =N14 -> 22060.05 | P15: 0 | Q15: 14912 | R15: =R14+O15+P15-Q15 -> 574864.59 | S15: =S14+O15 -> 545040.6 | T15: =Assumptions!$D$18*1*$C15 -> 6000 | U15: 5445 | V15: =T15*Assumptions!$B$12+U15*Assumptions!$B$14 -> 143529.17 | W15: =V14 -> 124029.93 | X15: 0 | Y15: 14912 | Z15: =Z14+W15+X15-Y15 -> 2923609 | AA15: =AA14+W15 -> 2893785
A16: 2027-11 | B16: 1 | C16: 0.06 | D16: =Assumptions!$B$18*1*$C16 -> 480 | E16: 144.8 | F16: =D16*Assumptions!$B$12+E16*Assumptions!$B$14 -> 9089.77 | G16: =F15 -> 6141.02 | H16: 0 | I16: 1520.33 | J16: =J15+G16+H16-I16 -> 124664.47 | K16: =K15+G16 -> 138347.47 | L16: =Assumptions!$C$18*1*$C16 -> 1800 | M16: 1068 | N16: =L16*Assumptions!$B$12+M16*Assumptions!$B$14 -> 38406.08 | O16: =N15 -> 26212.89 | P16: 0 | Q16: 14912 | R16: =R15+O16+P16-Q16 -> 586165.49 | S16: =S15+O16 -> 571253.49 | T16: =Assumptions!$D$18*1*$C16 -> 9000 | U16: 7335 | V16: =T16*Assumptions!$B$12+U16*Assumptions!$B$14 -> 208444.34 | W16: =V15 -> 143529.17 | X16: 0 | Y16: 14912 | Z16: =Z15+W16+X16-Y16 -> 3052226.1 | AA16: =AA15+W16 -> 3037314.1
A17: 2027-12 | B17: 2 | C17: 0.15 | D17: =Assumptions!$B$18*Assumptions!$B$23*$C17 -> 420 | E17: 100.8 | F17: =D17*Assumptions!$B$12+E17*Assumptions!$B$14 -> 7740.46 | G17: =F16 -> 9089.77 | H17: 0 | I17: 1520.33 | J17: =J16+G17+H17-I17 -> 132233.91 | K17: =K16+G17 -> 147437.24 | L17: =Assumptions!$C$18*Assumptions!$B$23*$C17 -> 1575 | M17: 740.25 | N17: =L17*Assumptions!$B$12+M17*Assumptions!$B$14 -> 32007.13 | O17: =N16 -> 38406.08 | P17: 0 | Q17: 14912 | R17: =R16+O17+P17-Q17 -> 609659.57 | S17: =S16+O17 -> 609659.57 | T17: =Assumptions!$D$18*Assumptions!$B$23*$C17 -> 7875 | U17: 4961.25 | V17: =T17*Assumptions!$B$12+U17*Assumptions!$B$14 -> 170402.32 | W17: =V16 -> 208444.34 | X17: 0 | Y17: 14912 | Z17: =Z16+W17+X17-Y17 -> 3245758.5 | AA17: =AA16+W17 -> 3245758.5
A18: 2028-01 | B18: 2 | C18: 0.1 | D18: =Assumptions!$B$18*Assumptions!$B$23*$C18 -> 280 | E18: 67.2 | F18: =D18*Assumptions!$B$12+E18*Assumptions!$B$14 -> 5160.3 | G18: =F17 -> 7740.46 | H18: 0 | I18: 1520.33 | J18: =J17+G18+H18-I18 -> 138454.03 | K18: =K17+G18 -> 155177.7 | L18: =Assumptions!$C$18*Assumptions!$B$23*$C18 -> 1050 | M18: 493.5 | N18: =L18*Assumptions!$B$12+M18*Assumptions!$B$14 -> 21338.09 | O18: =N17 -> 32007.13 | P18: 0 | Q18: 2187 | R18: =R17+O18+P18-Q18 -> 639479.71 | S18: =S17+O18 -> 641666.7 | T18: =Assumptions!$D$18*Assumptions!$B$23*$C18 -> 5250 | U18: 3307.5 | V18: =T18*Assumptions!$B$12+U18*Assumptions!$B$14 -> 113601.55 | W18: =V17 -> 170402.32 | X18: 0 | Y18: 2187 | Z18: =Z17+W18+X18-Y18 -> 3413973.8 | AA18: =AA17+W18 -> 3416160.8
A19: 2028-02 | B19: 2 | C19: 0.07 | D19: =Assumptions!$B$18*Assumptions!$B$23*$C19 -> 196 | E19: 47.04 | F19: =D19*Assumptions!$B$12+E19*Assumptions!$B$14 -> 3612.21 | G19: =F18 -> 5160.3 | H19: 0 | I19: 1520.33 | J19: =J18+G19+H19-I19 -> 142094.01 | K19: =K18+G19 -> 160338 | L19: =Assumptions!$C$18*Assumptions!$B$23*$C19 -> 735 | M19: 345.45 | N19: =L19*Assumptions!$B$12+M19*Assumptions!$B$14 -> 14936.66 | O19: =N18 -> 21338.09 | P19: 0 | Q19: 2187 | R19: =R18+O19+P19-Q19 -> 658630.79 | S19: =S18+O19 -> 663004.79 | T19: =Assumptions!$D$18*Assumptions!$B$23*$C19 -> 3675 | U19: 2315.25 | V19: =T19*Assumptions!$B$12+U19*Assumptions!$B$14 -> 79521.08 | W19: =V18 -> 113601.55 | X19: 0 | Y19: 2187 | Z19: =Z18+W19+X19-Y19 -> 3525388.3 | AA19: =AA18+W19 -> 3529762.3
A20: 2028-03 | B20: 2 | C20: 0.07 | D20: =Assumptions!$B$18*Assumptions!$B$23*$C20 -> 196 | E20: 47.04 | F20: =D20*Assumptions!$B$12+E20*Assumptions!$B$14 -> 3612.21 | G20: =F19 -> 3612.21 | H20: 0 | I20: 1520.33 | J20: =J19+G20+H20-I20 -> 144185.89 | K20: =K19+G20 -> 163950.21 | L20: =Assumptions!$C$18*Assumptions!$B$23*$C20 -> 735 | M20: 345.45 | N20: =L20*Assumptions!$B$12+M20*Assumptions!$B$14 -> 14936.66 | O20: =N19 -> 14936.66 | P20: 0 | Q20: 2187 | R20: =R19+O20+P20-Q20 -> 671380.46 | S20: =S19+O20 -> 677941.45 | T20: =Assumptions!$D$18*Assumptions!$B$23*$C20 -> 3675 | U20: 2315.25 | V20: =T20*Assumptions!$B$12+U20*Assumptions!$B$14 -> 79521.08 | W20: =V19 -> 79521.08 | X20: 0 | Y20: 2187 | Z20: =Z19+W20+X20-Y20 -> 3602722.4 | AA20: =AA19+W20 -> 3609283.4
A21: 2028-04 | B21: 2 | C21: 0.06 | D21: =Assumptions!$B$18*Assumptions!$B$23*$C21 -> 168 | E21: 40.32 | F21: =D21*Assumptions!$B$12+E21*Assumptions!$B$14 -> 3096.18 | G21: =F20 -> 3612.21 | H21: 0 | I21: 1520.33 | J21: =J20+G21+H21-I21 -> 146277.77 | K21: =K20+G21 -> 167562.42 | L21: =Assumptions!$C$18*Assumptions!$B$23*$C21 -> 630 | M21: 296.1 | N21: =L21*Assumptions!$B$12+M21*Assumptions!$B$14 -> 12802.85 | O21: =N20 -> 14936.66 | P21: 0 | Q21: 2187 | R21: =R20+O21+P21-Q21 -> 684130.12 | S21: =S20+O21 -> 692878.11 | T21: =Assumptions!$D$18*Assumptions!$B$23*$C21 -> 3150 | U21: 1984.5 | V21: =T21*Assumptions!$B$12+U21*Assumptions!$B$14 -> 68160.93 | W21: =V20 -> 79521.08 | X21: 0 | Y21: 2187 | Z21: =Z20+W21+X21-Y21 -> 3680056.5 | AA21: =AA20+W21 -> 3688804.5
A22: 2028-05 | B22: 2 | C22: 0.06 | D22: =Assumptions!$B$18*Assumptions!$B$23*$C22 -> 168 | E22: 40.32 | F22: =D22*Assumptions!$B$12+E22*Assumptions!$B$14 -> 3096.18 | G22: =F21 -> 3096.18 | H22: 0 | I22: 1520.33 | J22: =J21+G22+H22-I22 -> 147853.62 | K22: =K21+G22 -> 170658.61 | L22: =Assumptions!$C$18*Assumptions!$B$23*$C22 -> 630 | M22: 296.1 | N22: =L22*Assumptions!$B$12+M22*Assumptions!$B$14 -> 12802.85 | O22: =N21 -> 12802.85 | P22: 0 | Q22: 2187 | R22: =R21+O22+P22-Q22 -> 694745.98 | S22: =S21+O22 -> 705680.96 | T22: =Assumptions!$D$18*Assumptions!$B$23*$C22 -> 3150 | U22: 1984.5 | V22: =T22*Assumptions!$B$12+U22*Assumptions!$B$14 -> 68160.93 | W22: =V21 -> 68160.93 | X22: 0 | Y22: 2187 | Z22: =Z21+W22+X22-Y22 -> 3746030.4 | AA22: =AA21+W22 -> 3756965.4
A23: 2028-06 | B23: 2 | C23: 0.12 | D23: =Assumptions!$B$18*Assumptions!$B$23*$C23 -> 336 | E23: 80.64 | F23: =D23*Assumptions!$B$12+E23*Assumptions!$B$14 -> 6192.36 | G23: =F22 -> 3096.18 | H23: 0 | I23: 1520.33 | J23: =J22+G23+H23-I23 -> 149429.48 | K23: =K22+G23 -> 173754.79 | L23: =Assumptions!$C$18*Assumptions!$B$23*$C23 -> 1260 | M23: 592.2 | N23: =L23*Assumptions!$B$12+M23*Assumptions!$B$14 -> 25605.7 | O23: =N22 -> 12802.85 | P23: 0 | Q23: 2187 | R23: =R22+O23+P23-Q23 -> 705361.83 | S23: =S22+O23 -> 718483.81 | T23: =Assumptions!$D$18*Assumptions!$B$23*$C23 -> 6300 | U23: 3969 | V23: =T23*Assumptions!$B$12+U23*Assumptions!$B$14 -> 136321.86 | W23: =V22 -> 68160.93 | X23: 0 | Y23: 2187 | Z23: =Z22+W23+X23-Y23 -> 3812004.4 | AA23: =AA22+W23 -> 3825126.4
A24: 2028-07 | B24: 2 | C24: 0.08 | D24: =Assumptions!$B$18*Assumptions!$B$23*$C24 -> 224 | E24: 53.76 | F24: =D24*Assumptions!$B$12+E24*Assumptions!$B$14 -> 4128.24 | G24: =F23 -> 6192.36 | H24: 0 | I24: 1520.33 | J24: =J23+G24+H24-I24 -> 154101.51 | K24: =K23+G24 -> 179947.15 | L24: =Assumptions!$C$18*Assumptions!$B$23*$C24 -> 840 | M24: 394.8 | N24: =L24*Assumptions!$B$12+M24*Assumptions!$B$14 -> 17070.47 | O24: =N23 -> 25605.7 | P24: 0 | Q24: 2187 | R24: =R23+O24+P24-Q24 -> 728780.54 | S24: =S23+O24 -> 744089.51 | T24: =Assumptions!$D$18*Assumptions!$B$23*$C24 -> 4200 | U24: 2646 | V24: =T24*Assumptions!$B$12+U24*Assumptions!$B$14 -> 90881.24 | W24: =V23 -> 136321.86 | X24: 0 | Y24: 2187 | Z24: =Z23+W24+X24-Y24 -> 3946139.2 | AA24: =AA23+W24 -> 3961448.2
A25: 2028-08 | B25: 2 | C25: 0.06 | D25: =Assumptions!$B$18*Assumptions!$B$23*$C25 -> 168 | E25: 40.32 | F25: =D25*Assumptions!$B$12+E25*Assumptions!$B$14 -> 3096.18 | G25: =F24 -> 4128.24 | H25: 0 | I25: 1520.33 | J25: =J24+G25+H25-I25 -> 156709.42 | K25: =K24+G25 -> 184075.4 | L25: =Assumptions!$C$18*Assumptions!$B$23*$C25 -> 630 | M25: 296.1 | N25: =L25*Assumptions!$B$12+M25*Assumptions!$B$14 -> 12802.85 | O25: =N24 -> 17070.47 | P25: 0 | Q25: 2187 | R25: =R24+O25+P25-Q25 -> 743664.01 | S25: =S24+O25 -> 761159.98 | T25: =Assumptions!$D$18*Assumptions!$B$23*$C25 -> 3150 | U25: 1984.5 | V25: =T25*Assumptions!$B$12+U25*Assumptions!$B$14 -> 68160.93 | W25: =V24 -> 90881.24 | X25: 0 | Y25: 2187 | Z25: =Z24+W25+X25-Y25 -> 4034833.5 | AA25: =AA24+W25 -> 4052329.4
A26: 2028-09 | B26: 2 | C26: 0.06 | D26: =Assumptions!$B$18*Assumptions!$B$23*$C26 -> 168 | E26: 40.32 | F26: =D26*Assumptions!$B$12+E26*Assumptions!$B$14 -> 3096.18 | G26: =F25 -> 3096.18 | H26: 0 | I26: 1520.33 | J26: =J25+G26+H26-I26 -> 158285.28 | K26: =K25+G26 -> 187171.58 | L26: =Assumptions!$C$18*Assumptions!$B$23*$C26 -> 630 | M26: 296.1 | N26: =L26*Assumptions!$B$12+M26*Assumptions!$B$14 -> 12802.85 | O26: =N25 -> 12802.85 | P26: 0 | Q26: 2187 | R26: =R25+O26+P26-Q26 -> 754279.86 | S26: =S25+O26 -> 773962.83 | T26: =Assumptions!$D$18*Assumptions!$B$23*$C26 -> 3150 | U26: 1984.5 | V26: =T26*Assumptions!$B$12+U26*Assumptions!$B$14 -> 68160.93 | W26: =V25 -> 68160.93 | X26: 0 | Y26: 2187 | Z26: =Z25+W26+X26-Y26 -> 4100807.4 | AA26: =AA25+W26 -> 4120490.4
A27: 2028-10 | B27: 2 | C27: 0.07 | D27: =Assumptions!$B$18*Assumptions!$B$23*$C27 -> 196 | E27: 47.04 | F27: =D27*Assumptions!$B$12+E27*Assumptions!$B$14 -> 3612.21 | G27: =F26 -> 3096.18 | H27: 0 | I27: 1520.33 | J27: =J26+G27+H27-I27 -> 159861.13 | K27: =K26+G27 -> 190267.76 | L27: =Assumptions!$C$18*Assumptions!$B$23*$C27 -> 735 | M27: 345.45 | N27: =L27*Assumptions!$B$12+M27*Assumptions!$B$14 -> 14936.66 | O27: =N26 -> 12802.85 | P27: 0 | Q27: 2187 | R27: =R26+O27+P27-Q27 -> 764895.72 | S27: =S26+O27 -> 786765.68 | T27: =Assumptions!$D$18*Assumptions!$B$23*$C27 -> 3675 | U27: 2315.25 | V27: =T27*Assumptions!$B$12+U27*Assumptions!$B$14 -> 79521.08 | W27: =V26 -> 68160.93 | X27: 0 | Y27: 2187 | Z27: =Z26+W27+X27-Y27 -> 4166781.3 | AA27: =AA26+W27 -> 4188651.3
A28: 2028-11 | B28: 2 | C28: 0.1 | D28: =Assumptions!$B$18*Assumptions!$B$23*$C28 -> 280 | E28: 67.2 | F28: =D28*Assumptions!$B$12+E28*Assumptions!$B$14 -> 5160.3 | G28: =F27 -> 3612.21 | H28: 0 | I28: 2562 | J28: =J27+G28+H28-I28 -> 160911.35 | K28: =K27+G28 -> 193879.97 | L28: =Assumptions!$C$18*Assumptions!$B$23*$C28 -> 1050 | M28: 493.5 | N28: =L28*Assumptions!$B$12+M28*Assumptions!$B$14 -> 21338.09 | O28: =N27 -> 14936.66 | P28: 0 | Q28: 3228.66 | R28: =R27+O28+P28-Q28 -> 776603.71 | S28: =S27+O28 -> 801702.34 | T28: =Assumptions!$D$18*Assumptions!$B$23*$C28 -> 5250 | U28: 3307.5 | V28: =T28*Assumptions!$B$12+U28*Assumptions!$B$14 -> 113601.55 | W28: =V27 -> 79521.08 | X28: 0 | Y28: 3228.66 | Z28: =Z27+W28+X28-Y28 -> 4243073.8 | AA28: =AA27+W28 -> 4268172.4
A29: 2028-12 | B29: 3 | C29: 0.15 | D29: =Assumptions!$B$18*Assumptions!$B$24*$C29 -> 180 | E29: 43.2 | F29: =D29*Assumptions!$B$12+E29*Assumptions!$B$14 -> 3317.34 | G29: =F28 -> 5160.3 | H29: 0 | I29: 2562 | J29: =J28+G29+H29-I29 -> 163509.65 | K29: =K28+G29 -> 199040.28 | L29: =Assumptions!$C$18*Assumptions!$B$24*$C29 -> 675 | M29: 317.25 | N29: =L29*Assumptions!$B$12+M29*Assumptions!$B$14 -> 13717.34 | O29: =N28 -> 21338.09 | P29: 0 | Q29: 3228.66 | R29: =R28+O29+P29-Q29 -> 794713.14 | S29: =S28+O29 -> 823040.42 | T29: =Assumptions!$D$18*Assumptions!$B$24*$C29 -> 3375 | U29: 2126.25 | V29: =T29*Assumptions!$B$12+U29*Assumptions!$B$14 -> 73029.57 | W29: =V28 -> 113601.55 | X29: 0 | Y29: 3228.66 | Z29: =Z28+W29+X29-Y29 -> 4353446.6 | AA29: =AA28+W29 -> 4381773.9
A30: 2029-01 | B30: 3 | C30: 0.1 | D30: =Assumptions!$B$18*Assumptions!$B$24*$C30 -> 120 | E30: 28.8 | F30: =D30*Assumptions!$B$12+E30*Assumptions!$B$14 -> 2211.56 | G30: =F29 -> 3317.34 | H30: 0 | I30: 2562 | J30: =J29+G30+H30-I30 -> 164264.99 | K30: =K29+G30 -> 202357.61 | L30: =Assumptions!$C$18*Assumptions!$B$24*$C30 -> 450 | M30: 211.5 | N30: =L30*Assumptions!$B$12+M30*Assumptions!$B$14 -> 9144.89 | O30: =N29 -> 13717.34 | P30: 0 | Q30: 3228.66 | R30: =R29+O30+P30-Q30 -> 805201.81 | S30: =S29+O30 -> 836757.77 | T30: =Assumptions!$D$18*Assumptions!$B$24*$C30 -> 2250 | U30: 1417.5 | V30: =T30*Assumptions!$B$12+U30*Assumptions!$B$14 -> 48686.38 | W30: =V29 -> 73029.57 | X30: 0 | Y30: 3228.66 | Z30: =Z29+W30+X30-Y30 -> 4423247.5 | AA30: =AA29+W30 -> 4454803.5
A31: 2029-02 | B31: 3 | C31: 0.07 | D31: =Assumptions!$B$18*Assumptions!$B$24*$C31 -> 84 | E31: 20.16 | F31: =D31*Assumptions!$B$12+E31*Assumptions!$B$14 -> 1548.09 | G31: =F30 -> 2211.56 | H31: 0 | I31: 2562 | J31: =J30+G31+H31-I31 -> 163914.56 | K31: =K30+G31 -> 204569.17 | L31: =Assumptions!$C$18*Assumptions!$B$24*$C31 -> 315 | M31: 148.05 | N31: =L31*Assumptions!$B$12+M31*Assumptions!$B$14 -> 6401.43 | O31: =N30 -> 9144.89 | P31: 0 | Q31: 3228.66 | R31: =R30+O31+P31-Q31 -> 811118.04 | S31: =S30+O31 -> 845902.66 | T31: =Assumptions!$D$18*Assumptions!$B$24*$C31 -> 1575 | U31: 992.25 | V31: =T31*Assumptions!$B$12+U31*Assumptions!$B$14 -> 34080.46 | W31: =V30 -> 48686.38 | X31: 0 | Y31: 3228.66 | Z31: =Z30+W31+X31-Y31 -> 4468705.2 | AA31: =AA30+W31 -> 4503489.9
A32: 2029-03 | B32: 3 | C32: 0.07 | D32: =Assumptions!$B$18*Assumptions!$B$24*$C32 -> 84 | E32: 20.16 | F32: =D32*Assumptions!$B$12+E32*Assumptions!$B$14 -> 1548.09 | G32: =F31 -> 1548.09 | H32: 0 | I32: 2562 | J32: =J31+G32+H32-I32 -> 162900.65 | K32: =K31+G32 -> 206117.26 | L32: =Assumptions!$C$18*Assumptions!$B$24*$C32 -> 315 | M32: 148.05 | N32: =L32*Assumptions!$B$12+M32*Assumptions!$B$14 -> 6401.43 | O32: =N31 -> 6401.43 | P32: 0 | Q32: 3228.66 | R32: =R31+O32+P32-Q32 -> 814290.81 | S32: =S31+O32 -> 852304.08 | T32: =Assumptions!$D$18*Assumptions!$B$24*$C32 -> 1575 | U32: 992.25 | V32: =T32*Assumptions!$B$12+U32*Assumptions!$B$14 -> 34080.46 | W32: =V31 -> 34080.46 | X32: 0 | Y32: 3228.66 | Z32: =Z31+W32+X32-Y32 -> 4499557 | AA32: =AA31+W32 -> 4537570.3
A33: 2029-04 | B33: 3 | C33: 0.06 | D33: =Assumptions!$B$18*Assumptions!$B$24*$C33 -> 72 | E33: 17.28 | F33: =D33*Assumptions!$B$12+E33*Assumptions!$B$14 -> 1326.94 | G33: =F32 -> 1548.09 | H33: 0 | I33: 2562 | J33: =J32+G33+H33-I33 -> 161886.75 | K33: =K32+G33 -> 207665.35 | L33: =Assumptions!$C$18*Assumptions!$B$24*$C33 -> 270 | M33: 126.9 | N33: =L33*Assumptions!$B$12+M33*Assumptions!$B$14 -> 5486.94 | O33: =N32 -> 6401.43 | P33: 0 | Q33: 3228.66 | R33: =R32+O33+P33-Q33 -> 817463.57 | S33: =S32+O33 -> 858705.51 | T33: =Assumptions!$D$18*Assumptions!$B$24*$C33 -> 1350 | U33: 850.5 | V33: =T33*Assumptions!$B$12+U33*Assumptions!$B$14 -> 29211.83 | W33: =V32 -> 34080.46 | X33: 0 | Y33: 3228.66 | Z33: =Z32+W33+X33-Y33 -> 4530408.8 | AA33: =AA32+W33 -> 4571650.8
A34: 2029-05 | B34: 3 | C34: 0.06 | D34: =Assumptions!$B$18*Assumptions!$B$24*$C34 -> 72 | E34: 17.28 | F34: =D34*Assumptions!$B$12+E34*Assumptions!$B$14 -> 1326.94 | G34: =F33 -> 1326.94 | H34: 0 | I34: 2562 | J34: =J33+G34+H34-I34 -> 160651.68 | K34: =K33+G34 -> 208992.29 | L34: =Assumptions!$C$18*Assumptions!$B$24*$C34 -> 270 | M34: 126.9 | N34: =L34*Assumptions!$B$12+M34*Assumptions!$B$14 -> 5486.94 | O34: =N33 -> 5486.94 | P34: 0 | Q34: 3228.66 | R34: =R33+O34+P34-Q34 -> 819721.84 | S34: =S33+O34 -> 864192.45 | T34: =Assumptions!$D$18*Assumptions!$B$24*$C34 -> 1350 | U34: 850.5 | V34: =T34*Assumptions!$B$12+U34*Assumptions!$B$14 -> 29211.83 | W34: =V33 -> 29211.83 | X34: 0 | Y34: 3228.66 | Z34: =Z33+W34+X34-Y34 -> 4556392 | AA34: =AA33+W34 -> 4600862.6
A35: 2029-06 | B35: 3 | C35: 0.12 | D35: =Assumptions!$B$18*Assumptions!$B$24*$C35 -> 144 | E35: 34.56 | F35: =D35*Assumptions!$B$12+E35*Assumptions!$B$14 -> 2653.87 | G35: =F34 -> 1326.94 | H35: 0 | I35: 2562 | J35: =J34+G35+H35-I35 -> 159416.62 | K35: =K34+G35 -> 210319.22 | L35: =Assumptions!$C$18*Assumptions!$B$24*$C35 -> 540 | M35: 253.8 | N35: =L35*Assumptions!$B$12+M35*Assumptions!$B$14 -> 10973.87 | O35: =N34 -> 5486.94 | P35: 0 | Q35: 3228.66 | R35: =R34+O35+P35-Q35 -> 821980.11 | S35: =S34+O35 -> 869679.38 | T35: =Assumptions!$D$18*Assumptions!$B$24*$C35 -> 2700 | U35: 1701 | V35: =T35*Assumptions!$B$12+U35*Assumptions!$B$14 -> 58423.65 | W35: =V34 -> 29211.83 | X35: 0 | Y35: 3228.66 | Z35: =Z34+W35+X35-Y35 -> 4582375.2 | AA35: =AA34+W35 -> 4630074.4
A36: 2029-07 | B36: 3 | C36: 0.08 | D36: =Assumptions!$B$18*Assumptions!$B$24*$C36 -> 96 | E36: 23.04 | F36: =D36*Assumptions!$B$12+E36*Assumptions!$B$14 -> 1769.25 | G36: =F35 -> 2653.87 | H36: 0 | I36: 2562 | J36: =J35+G36+H36-I36 -> 159508.5 | K36: =K35+G36 -> 212973.09 | L36: =Assumptions!$C$18*Assumptions!$B$24*$C36 -> 360 | M36: 169.2 | N36: =L36*Assumptions!$B$12+M36*Assumptions!$B$14 -> 7315.91 | O36: =N35 -> 10973.87 | P36: 0 | Q36: 3228.66 | R36: =R35+O36+P36-Q36 -> 829725.32 | S36: =S35+O36 -> 880653.25 | T36: =Assumptions!$D$18*Assumptions!$B$24*$C36 -> 1800 | U36: 1134 | V36: =T36*Assumptions!$B$12+U36*Assumptions!$B$14 -> 38949.1 | W36: =V35 -> 58423.65 | X36: 0 | Y36: 3228.66 | Z36: =Z35+W36+X36-Y36 -> 4637570.2 | AA36: =AA35+W36 -> 4688498.1
A37: 2029-08 | B37: 3 | C37: 0.06 | D37: =Assumptions!$B$18*Assumptions!$B$24*$C37 -> 72 | E37: 17.28 | F37: =D37*Assumptions!$B$12+E37*Assumptions!$B$14 -> 1326.94 | G37: =F36 -> 1769.25 | H37: 0 | I37: 2562 | J37: =J36+G37+H37-I37 -> 158715.75 | K37: =K36+G37 -> 214742.34 | L37: =Assumptions!$C$18*Assumptions!$B$24*$C37 -> 270 | M37: 126.9 | N37: =L37*Assumptions!$B$12+M37*Assumptions!$B$14 -> 5486.94 | O37: =N36 -> 7315.91 | P37: 0 | Q37: 3228.66 | R37: =R36+O37+P37-Q37 -> 833812.58 | S37: =S36+O37 -> 887969.17 | T37: =Assumptions!$D$18*Assumptions!$B$24*$C37 -> 1350 | U37: 850.5 | V37: =T37*Assumptions!$B$12+U37*Assumptions!$B$14 -> 29211.83 | W37: =V36 -> 38949.1 | X37: 0 | Y37: 3228.66 | Z37: =Z36+W37+X37-Y37 -> 4673290.6 | AA37: =AA36+W37 -> 4727447.2
A38: 2029-09 | B38: 3 | C38: 0.06 | D38: =Assumptions!$B$18*Assumptions!$B$24*$C38 -> 72 | E38: 17.28 | F38: =D38*Assumptions!$B$12+E38*Assumptions!$B$14 -> 1326.94 | G38: =F37 -> 1326.94 | H38: 0 | I38: 2562 | J38: =J37+G38+H38-I38 -> 157480.69 | K38: =K37+G38 -> 216069.28 | L38: =Assumptions!$C$18*Assumptions!$B$24*$C38 -> 270 | M38: 126.9 | N38: =L38*Assumptions!$B$12+M38*Assumptions!$B$14 -> 5486.94 | O38: =N37 -> 5486.94 | P38: 0 | Q38: 3228.66 | R38: =R37+O38+P38-Q38 -> 836070.85 | S38: =S37+O38 -> 893456.11 | T38: =Assumptions!$D$18*Assumptions!$B$24*$C38 -> 1350 | U38: 850.5 | V38: =T38*Assumptions!$B$12+U38*Assumptions!$B$14 -> 29211.83 | W38: =V37 -> 29211.83 | X38: 0 | Y38: 3228.66 | Z38: =Z37+W38+X38-Y38 -> 4699273.8 | AA38: =AA37+W38 -> 4756659
A39: 2029-10 | B39: 3 | C39: 0.07 | D39: =Assumptions!$B$18*Assumptions!$B$24*$C39 -> 84 | E39: 20.16 | F39: =D39*Assumptions!$B$12+E39*Assumptions!$B$14 -> 1548.09 | G39: =F38 -> 1326.94 | H39: 0 | I39: 2562 | J39: =J38+G39+H39-I39 -> 156245.63 | K39: =K38+G39 -> 217396.21 | L39: =Assumptions!$C$18*Assumptions!$B$24*$C39 -> 315 | M39: 148.05 | N39: =L39*Assumptions!$B$12+M39*Assumptions!$B$14 -> 6401.43 | O39: =N38 -> 5486.94 | P39: 0 | Q39: 3228.66 | R39: =R38+O39+P39-Q39 -> 838329.12 | S39: =S38+O39 -> 898943.04 | T39: =Assumptions!$D$18*Assumptions!$B$24*$C39 -> 1575 | U39: 992.25 | V39: =T39*Assumptions!$B$12+U39*Assumptions!$B$14 -> 34080.46 | W39: =V38 -> 29211.83 | X39: 0 | Y39: 3228.66 | Z39: =Z38+W39+X39-Y39 -> 4725256.9 | AA39: =AA38+W39 -> 4785870.8
A40: 2029-11 | B40: 3 | C40: 0.1 | D40: =Assumptions!$B$18*Assumptions!$B$24*$C40 -> 120 | E40: 28.8 | F40: =D40*Assumptions!$B$12+E40*Assumptions!$B$14 -> 2211.56 | G40: =F39 -> 1548.09 | H40: 0 | I40: 2562 | J40: =J39+G40+H40-I40 -> 155231.72 | K40: =K39+G40 -> 218944.3 | L40: =Assumptions!$C$18*Assumptions!$B$24*$C40 -> 450 | M40: 211.5 | N40: =L40*Assumptions!$B$12+M40*Assumptions!$B$14 -> 9144.89 | O40: =N39 -> 6401.43 | P40: 0 | Q40: 3228.66 | R40: =R39+O40+P40-Q40 -> 841501.88 | S40: =S39+O40 -> 905344.47 | T40: =Assumptions!$D$18*Assumptions!$B$24*$C40 -> 2250 | U40: 1417.5 | V40: =T40*Assumptions!$B$12+U40*Assumptions!$B$14 -> 48686.38 | W40: =V39 -> 34080.46 | X40: 0 | Y40: 3228.66 | Z40: =Z39+W40+X40-Y40 -> 4756108.7 | AA40: =AA39+W40 -> 4819951.3
...
