Workbook

Sheet Summary
A1: ABANDONED funding request
A2: Sarab Studio. Three options over 14 months, November 2026 to December 2027. All amounts in AED.
A4: What we receive | B4: Lean | C4: Standard | D4: Max
A5: Total ask | B5: ='Lean'!$F$16 -> 550000 | C5: ='Standard'!$F$16 -> 620000 | D5: ='Max'!$F$16 -> 730000
A6: Tranche 1, at the start (November 2026) | B6: ='Lean'!$B$16 -> 290400 | C6: ='Standard'!$B$16 -> 344900 | D6: ='Max'!$B$16 -> 415400
A7: Tranche 2, at 10,000 copies and 75% positive reviews (March 2027) | B7: ='Lean'!$C$16 -> 134000 | C7: ='Standard'!$C$16 -> 140000 | D7: ='Max'!$C$16 -> 164000
A8: Tranche 3, at 20,000 copies (September 2027) | B8: ='Lean'!$D$16 -> 74000 | C8: ='Standard'!$D$16 -> 78500 | D8: ='Max'!$D$16 -> 83000
A9: Reserve, held back for overruns | B9: ='Lean'!$E$16 -> 51600 | C9: ='Standard'!$E$16 -> 56600 | D9: ='Max'!$E$16 -> 67600
A10: Total ask in US dollars | B10: =B5/Assumptions!$B$16 -> 149761.74 | C10: =C5/Assumptions!$B$16 -> 168822.33 | D10: =D5/Assumptions!$B$16 -> 198774.68
A12: Where the money goes | B12: Lean | C12: Standard | D12: Max
A13: Founder pay (3 x 5,000 a month) | B13: ='Lean'!$F$5 -> 210000 | C13: ='Standard'!$F$5 -> 210000 | D13: ='Max'!$F$5 -> 210000
A14: Marketing and community | B14: ='Lean'!$F$6 -> 160000 | C14: ='Standard'!$F$6 -> 210000 | D14: ='Max'!$F$6 -> 240000
A15: Software, website and domain | B15: ='Lean'!$F$7 -> 25000 | C15: ='Standard'!$F$7 -> 25000 | D15: ='Max'!$F$7 -> 25000
A16: Work setups (3 x 20,000) | B16: ='Lean'!$F$8 -> 60000 | C16: ='Standard'!$F$8 -> 60000 | D16: ='Max'!$F$8 -> 60000
A17: Steam Deck for testing | B17: ='Lean'!$F$9 -> 2400 | C17: ='Standard'!$F$9 -> 2400 | D17: ='Max'!$F$9 -> 2400
A18: Legal, accounting and bookkeeping | B18: ='Lean'!$F$10 -> 20000 | C18: ='Standard'!$F$10 -> 20000 | D18: ='Max'!$F$10 -> 20000
A19: Language checks (11 x 1,000) | B19: ='Lean'!$F$11 -> 11000 | C19: ='Standard'!$F$11 -> 11000 | D19: ='Max'!$F$11 -> 11000
A20: Events | B20: ='Lean'!$F$12 -> 10000 | C20: ='Standard'!$F$12 -> 10000 | D20: ='Max'!$F$12 -> 10000
A21: UAE freelancers (art, sound) | B21: ='Lean'!$F$13 -> 0 | C21: ='Standard'!$F$13 -> 15000 | D21: ='Max'!$F$13 -> 30000
A22: UAE interns (3 x 3,000 x 6 months) | B22: ='Lean'!$F$14 -> 0 | C22: ='Standard'!$F$14 -> 0 | D22: ='Max'!$F$14 -> 54000
A23: Spend | B23: =SUM(B13:B22) -> 498400 | C23: =SUM(C13:C22) -> 563400 | D23: =SUM(D13:D22) -> 662400
A24: Reserve | B24: ='Lean'!$E$16 -> 51600 | C24: ='Standard'!$E$16 -> 56600 | D24: ='Max'!$E$16 -> 67600
A25: Total ask | B25: =B23+B24 -> 550000 | C25: =C23+C24 -> 620000 | D25: =D23+D24 -> 730000
A27: Key figures | B27: Lean | C27: Standard | D27: Max
A28: Tranche 1 as a share of the total ask | B28: =B6/B5 -> 0.528 | C28: =C6/C5 -> 0.55629032 | D28: =D6/D5 -> 0.5690411
A29: Marketing as a share of spend | B29: =B14/B23 -> 0.32102729 | C29: =C14/C23 -> 0.37273695 | D29: =D14/D23 -> 0.36231884
A30: Copies to sell to earn back the total ask | B30: =B5/Assumptions!$C$12 -> 33424.391 | C30: =C5/Assumptions!$C$12 -> 37678.404 | D30: =D5/Assumptions!$C$12 -> 44363.283
A31: Room under Unity's USD 200,000 limit, before game sales (USD) | B31: =Assumptions!$B$17-B5/Assumptions!$B$16 -> 50238.257 | C31: =Assumptions!$B$17-C5/Assumptions!$B$16 -> 31177.672 | D31: =Assumptions!$B$17-D5/Assumptions!$B$16 -> 1225.3233
A33: Each copy earns the studio about AED 16.46 after regional prices, VAT, refunds, Steam's share and US withholding (see Assumptions).
A34: Tranche 2 is released at the end of February 2027 if at least 10,000 copies have sold and reviews are at least 75% positive.
A35: Tranche 3 is released in September 2027 if at least 20,000 copies have sold. The reserve is only drawn if costs run over.
A36: Unity's limit counts funding plus game revenue over 12 months. A plan above it, or one that sells past it, needs Unity Pro.

Sheet Lean
A1: Lean plan
A2: What each tranche pays for. All amounts in AED.
A4: Line | B4: Tranche 1 at start Nov 2026 | C4: Tranche 2 Mar 2027 10k copies, 75% reviews | D4: Tranche 3 Sep 2027 20k copies | E4: Reserve held back | F4: Line total | G4: How it is split
A5: Founder pay (3 x 5,000 a month) | B5: 60000 | C5: 90000 | D5: 60000 | E5: 0 | F5: =SUM(B5:E5) -> 210000 | G5: Zeyad, Yousef and Jihad at 5,000 a month each, for the months each tranche covers (4, 6 and 4)
A6: Marketing and community | B6: 160000 | C6: 0 | D6: 0 | E6: 0 | F6: =SUM(B6:E6) -> 160000 | G6: Full budget at the start
A7: Software, website and domain | B7: 7000 | C7: 11000 | D7: 7000 | E7: 0 | F7: =SUM(B7:E7) -> 25000 | G7: Monthly costs for the months each tranche covers (4, 6 and 4)
A8: Work setups (3 x 20,000) | B8: 40000 | C8: 20000 | D8: 0 | E8: 0 | F8: =SUM(B8:E8) -> 60000 | G8: Two setups now, the third with tranche 2
A9: Steam Deck for testing | B9: 2400 | C9: 0 | D9: 0 | E9: 0 | F9: =SUM(B9:E9) -> 2400 | G9: Bought before launch
A10: Legal, accounting and bookkeeping | B10: 10000 | C10: 6000 | D10: 4000 | E10: 0 | F10: =SUM(B10:E10) -> 20000 | G10: Company setup first, then running costs
A11: Language checks (11 x 1,000) | B11: 8000 | C11: 3000 | D11: 0 | E11: 0 | F11: =SUM(B11:E11) -> 11000 | G11: Launch text before December, DLC text in 2027
A12: Events | B12: 3000 | C12: 4000 | D12: 3000 | E12: 0 | F12: =SUM(B12:E12) -> 10000 | G12: Spread across the year
A13: UAE freelancers (art, sound) | B13: 0 | C13: 0 | D13: 0 | E13: 0 | F13: =SUM(B13:E13) -> 0 | G13: Not in this plan
A14: UAE interns (3 x 3,000 x 6 months) | B14: 0 | C14: 0 | D14: 0 | E14: 0 | F14: =SUM(B14:E14) -> 0 | G14: Not in this plan
A15: Reserve, held back for overruns | B15: 0 | C15: 0 | D15: 0 | E15: =F16-SUM(B5:D14) -> 51600 | F15: =SUM(B15:E15) -> 51600 | G15: Whatever is left between the spend and the total ask, about 10%
A16: Total we receive | B16: =SUM(B5:B15) -> 290400 | C16: =SUM(C5:C15) -> 134000 | D16: =SUM(D5:D15) -> 74000 | E16: =SUM(E5:E15) -> 51600 | F16: 550000 | G16: Total ask (blue: change it to move the reserve)
A17: Share of the total ask | B17: =B16/$F$16 -> 0.528 | C17: =C16/$F$16 -> 0.24363636 | D17: =D16/$F$16 -> 0.13454545 | E17: =E16/$F$16 -> 0.093818182 | F17: =F16/$F$16 -> 1
A19: Blue figures are inputs. Change a tranche amount and the line total, reserve and summary update.
A20: Tranche 2 is released at the end of February 2027 if at least 10,000 copies have sold and reviews are at least 75% positive.
A21: Tranche 3 is released in September 2027 if at least 20,000 copies have sold.

Sheet Standard
A1: Standard plan
A2: What each tranche pays for. All amounts in AED.
A4: Line | B4: Tranche 1 at start Nov 2026 | C4: Tranche 2 Mar 2027 10k copies, 75% reviews | D4: Tranche 3 Sep 2027 20k copies | E4: Reserve held back | F4: Line total | G4: How it is split
A5: Founder pay (3 x 5,000 a month) | B5: 60000 | C5: 90000 | D5: 60000 | E5: 0 | F5: =SUM(B5:E5) -> 210000 | G5: Zeyad, Yousef and Jihad at 5,000 a month each, for the months each tranche covers (4, 6 and 4)
A6: Marketing and community | B6: 210000 | C6: 0 | D6: 0 | E6: 0 | F6: =SUM(B6:E6) -> 210000 | G6: Full budget at the start
A7: Software, website and domain | B7: 7000 | C7: 11000 | D7: 7000 | E7: 0 | F7: =SUM(B7:E7) -> 25000 | G7: Monthly costs for the months each tranche covers (4, 6 and 4)
A8: Work setups (3 x 20,000) | B8: 40000 | C8: 20000 | D8: 0 | E8: 0 | F8: =SUM(B8:E8) -> 60000 | G8: Two setups now, the third with tranche 2
A9: Steam Deck for testing | B9: 2400 | C9: 0 | D9: 0 | E9: 0 | F9: =SUM(B9:E9) -> 2400 | G9: Bought before launch
A10: Legal, accounting and bookkeeping | B10: 10000 | C10: 6000 | D10: 4000 | E10: 0 | F10: =SUM(B10:E10) -> 20000 | G10: Company setup first, then running costs
A11: Language checks (11 x 1,000) | B11: 8000 | C11: 3000 | D11: 0 | E11: 0 | F11: =SUM(B11:E11) -> 11000 | G11: Launch text before December, DLC text in 2027
A12: Events | B12: 3000 | C12: 4000 | D12: 3000 | E12: 0 | F12: =SUM(B12:E12) -> 10000 | G12: Spread across the year
A13: UAE freelancers (art, sound) | B13: 4500 | C13: 6000 | D13: 4500 | E13: 0 | F13: =SUM(B13:E13) -> 15000 | G13: Spread across the year
A14: UAE interns (3 x 3,000 x 6 months) | B14: 0 | C14: 0 | D14: 0 | E14: 0 | F14: =SUM(B14:E14) -> 0 | G14: Not in this plan
A15: Reserve, held back for overruns | B15: 0 | C15: 0 | D15: 0 | E15: =F16-SUM(B5:D14) -> 56600 | F15: =SUM(B15:E15) -> 56600 | G15: Whatever is left between the spend and the total ask, about 10%
A16: Total we receive | B16: =SUM(B5:B15) -> 344900 | C16: =SUM(C5:C15) -> 140000 | D16: =SUM(D5:D15) -> 78500 | E16: =SUM(E5:E15) -> 56600 | F16: 620000 | G16: Total ask (blue: change it to move the reserve)
A17: Share of the total ask | B17: =B16/$F$16 -> 0.55629032 | C17: =C16/$F$16 -> 0.22580645 | D17: =D16/$F$16 -> 0.1266129 | E17: =E16/$F$16 -> 0.091290323 | F17: =F16/$F$16 -> 1
A19: Blue figures are inputs. Change a tranche amount and the line total, reserve and summary update.
A20: Tranche 2 is released at the end of February 2027 if at least 10,000 copies have sold and reviews are at least 75% positive.
A21: Tranche 3 is released in September 2027 if at least 20,000 copies have sold.

Sheet Max
A1: Max plan
A2: What each tranche pays for. All amounts in AED.
A4: Line | B4: Tranche 1 at start Nov 2026 | C4: Tranche 2 Mar 2027 10k copies, 75% reviews | D4: Tranche 3 Sep 2027 20k copies | E4: Reserve held back | F4: Line total | G4: How it is split
A5: Founder pay (3 x 5,000 a month) | B5: 60000 | C5: 90000 | D5: 60000 | E5: 0 | F5: =SUM(B5:E5) -> 210000 | G5: Zeyad, Yousef and Jihad at 5,000 a month each, for the months each tranche covers (4, 6 and 4)
A6: Marketing and community | B6: 240000 | C6: 0 | D6: 0 | E6: 0 | F6: =SUM(B6:E6) -> 240000 | G6: Full budget at the start
A7: Software, website and domain | B7: 7000 | C7: 11000 | D7: 7000 | E7: 0 | F7: =SUM(B7:E7) -> 25000 | G7: Monthly costs for the months each tranche covers (4, 6 and 4)
A8: Work setups (3 x 20,000) | B8: 40000 | C8: 20000 | D8: 0 | E8: 0 | F8: =SUM(B8:E8) -> 60000 | G8: Two setups now, the third with tranche 2
A9: Steam Deck for testing | B9: 2400 | C9: 0 | D9: 0 | E9: 0 | F9: =SUM(B9:E9) -> 2400 | G9: Bought before launch
A10: Legal, accounting and bookkeeping | B10: 10000 | C10: 6000 | D10: 4000 | E10: 0 | F10: =SUM(B10:E10) -> 20000 | G10: Company setup first, then running costs
A11: Language checks (11 x 1,000) | B11: 8000 | C11: 3000 | D11: 0 | E11: 0 | F11: =SUM(B11:E11) -> 11000 | G11: Launch text before December, DLC text in 2027
A12: Events | B12: 3000 | C12: 4000 | D12: 3000 | E12: 0 | F12: =SUM(B12:E12) -> 10000 | G12: Spread across the year
A13: UAE freelancers (art, sound) | B13: 9000 | C13: 12000 | D13: 9000 | E13: 0 | F13: =SUM(B13:E13) -> 30000 | G13: Spread across the year
A14: UAE interns (3 x 3,000 x 6 months) | B14: 36000 | C14: 18000 | D14: 0 | E14: 0 | F14: =SUM(B14:E14) -> 54000 | G14: November to February from tranche 1, March and April from tranche 2
A15: Reserve, held back for overruns | B15: 0 | C15: 0 | D15: 0 | E15: =F16-SUM(B5:D14) -> 67600 | F15: =SUM(B15:E15) -> 67600 | G15: Whatever is left between the spend and the total ask, about 10%
A16: Total we receive | B16: =SUM(B5:B15) -> 415400 | C16: =SUM(C5:C15) -> 164000 | D16: =SUM(D5:D15) -> 83000 | E16: =SUM(E5:E15) -> 67600 | F16: 730000 | G16: Total ask (blue: change it to move the reserve)
A17: Share of the total ask | B17: =B16/$F$16 -> 0.5690411 | C17: =C16/$F$16 -> 0.22465753 | D17: =D16/$F$16 -> 0.11369863 | E17: =E16/$F$16 -> 0.09260274 | F17: =F16/$F$16 -> 1
A19: Blue figures are inputs. Change a tranche amount and the line total, reserve and summary update.
A20: Tranche 2 is released at the end of February 2027 if at least 10,000 copies have sold and reviews are at least 75% positive.
A21: Tranche 3 is released in September 2027 if at least 20,000 copies have sold.

Sheet Assumptions
A1: Assumptions and checks
A2: Blue figures are inputs. Everything else in the workbook is worked out from them.
A4: What we keep from one sale
A5: Step | B5: Rate | C5: AED left
A6: List price ($9.99 tier) | C6: 36.7
A7: Average sale after regional prices and discounts | B7: 0.78 | C7: =C6*B7 -> 28.626
A8: Less VAT and sales tax inside the price | B8: 0.06 | C8: =C7*(1-B8) -> 26.90844
A9: Less refunds | B9: 0.04 | C9: =C8*(1-B9) -> 25.832102
A10: Less Steam's share | B10: 0.3 | C10: =C9*(1-B10) -> 18.082472
A11: Less US withholding: 30% tax on the 30% of sales from US buyers | B11: =0.3*0.3 -> 0.09 | C11: =C10*(1-B11) -> 16.455049
A12: Studio keeps per copy | C12: =C11 -> 16.455049
A14: Other inputs
A15: Input | B15: Value
A16: AED per US dollar (fixed peg) | B16: 3.6725
A17: Unity Personal limit, USD of funding plus revenue over 12 months | B17: 200000
A18: Founder pay a month, Zeyad | B18: 5000
A19: Founder pay a month, Yousef | B19: 5000
A20: Founder pay a month, Jihad | B20: 5000
A21: Work setups | B21: 3
A22: Price per setup | B22: 20000
A23: Languages checked by native speakers | B23: 11
A24: Price per language | B24: 1000
A25: Interns (Max plan only) | B25: 3
A26: Intern pay per month | B26: 3000
A27: Intern months | B27: 6
A29: Software, 14 months
A30: Item | B30: AED a month | C30: Count | D30: 14 months
A31: Claude Max (Zeyad, Yousef) | B31: 370 | C31: 2 | D31: =B31*C31*14 -> 10360
A32: ChatGPT Pro (Zeyad, Yousef) | B32: 375 | C32: 2 | D32: =B32*C32*14 -> 10500
A33: Claude Pro (Jihad) | B33: 75 | C33: 1 | D33: =B33*C33*14 -> 1050
A34: Google Workspace mailboxes on our domain | B34: 26 | C34: 3 | D34: =B34*C34*14 -> 1092
A35: Website hosting and builder | B35: 75 | C35: 1 | D35: =B35*C35*14 -> 1050
A36: Domain (AED 100 a year) | B36: 100 | C36: per year | D36: =B36*14/12 -> 116.66667
A37: Itemised total | D37: =SUM(D31:D36) -> 24168.667
A38: Budgeted, rounded up | D38: 25000
A39: Prices are the plans' list prices in dirhams. Check them before the meeting.
A41: Checks
A42: Check | B42: Lean | C42: Standard | D42: Max
A43: Founder pay equals the three monthly amounts x 14 months | B43: =IF('Lean'!$F$5=(Assumptions!$B$18+Assumptions!$B$19+Assumptions!$B$20)*14,"OK","CHECK") -> OK | C43: =IF('Standard'!$F$5=(Assumptions!$B$18+Assumptions!$B$19+Assumptions!$B$20)*14,"OK","CHECK") -> OK | D43: =IF('Max'!$F$5=(Assumptions!$B$18+Assumptions!$B$19+Assumptions!$B$20)*14,"OK","CHECK") -> OK
A44: Software equals the software budget | B44: =IF('Lean'!$F$7=Assumptions!$D$38,"OK","CHECK") -> OK | C44: =IF('Standard'!$F$7=Assumptions!$D$38,"OK","CHECK") -> OK | D44: =IF('Max'!$F$7=Assumptions!$D$38,"OK","CHECK") -> OK
...
